Workbook

Sheet user_table
A1: user_id | B1: gender | C1: age | D1: country | E1: device | F1: traffic_source
A2: 1001 | B2: Male | C2: 64 | D2: Australia | E2: Desktop | F2: Organic
A3: 1002 | B3: Female | C3: 29 | D3: UK | E3: Mobile | F3: Organic
A4: 1003 | B4: Female | C4: 33 | D4: Germany | E4: Mobile | F4: Social
A5: 1004 | B5: Female | C5: 41 | D5: Australia | E5: Desktop | F5: Paid
A6: 1005 | B6: Male | C6: 36 | D6: USA | E6: Desktop | F6: Email
A7: 1006 | B7: Male | C7: 25 | D7: Germany | E7: Mobile | F7: Organic
A8: 1007 | B8: Male | C8: 48 | D8: USA | E8: Mobile | F8: Organic
A9: 1008 | B9: Female | C9: 38 | D9: Australia | E9: Desktop | F9: Paid
A10: 1009 | B10: Female | C10: 34 | D10: USA | E10: Mobile | F10: Organic
A11: 1010 | B11: Female | C11: 40 | D11: Australia | E11: Desktop | F11: Organic
A12: 1011 | B12: Male | C12: 54 | D12: Australia | E12: Mobile | F12: Social
A13: 1012 | B13: Female | C13: 33 | D13: Australia | E13: Desktop | F13: Organic
... A1001: 2000 | B1001: Male | C1001: 23 | D1001: Australia | E1001: Mobile | F1001: Social

Sheet home_page
A1: user_id | B1: timestamp | C1: Gender | D1: Device | E1: Traffic Source | F1: Reached Search
A2: 1001 | B2: 45343.927 | C2: =VLOOKUP(A2, user_table!$A:$B, 2, FALSE) -> Male | D2: =VLOOKUP(A2, user_table!$A:$F, 5, FALSE) -> Desktop | E2: =VLOOKUP(A2, user_table!$A:$F, 6, FALSE) -> Organic | F2: =IF(ISNUMBER(MATCH(A2, search_page!$A:$A, 0)), "Yes", "No") -> Yes | H2: Row Labels | I2: Count of user_id
A3: 1002 | B3: 45331.901 | C3: =VLOOKUP(A3, user_table!$A:$B, 2, FALSE) -> Female | D3: =VLOOKUP(A3, user_table!$A:$F, 5, FALSE) -> Mobile | E3: =VLOOKUP(A3, user_table!$A:$F, 6, FALSE) -> Organic | F3: =IF(ISNUMBER(MATCH(A3, search_page!$A:$A, 0)), "Yes", "No") -> No | H3: Female | I3: 475
A4: 1003 | B4: 45339.649 | C4: =VLOOKUP(A4, user_table!$A:$B, 2, FALSE) -> Female | D4: =VLOOKUP(A4, user_table!$A:$F, 5, FALSE) -> Mobile | E4: =VLOOKUP(A4, user_table!$A:$F, 6, FALSE) -> Social | F4: =IF(ISNUMBER(MATCH(A4, search_page!$A:$A, 0)), "Yes", "No") -> Yes | H4: Male | I4: 525
A5: 1004 | B5: 45359.477 | C5: =VLOOKUP(A5, user_table!$A:$B, 2, FALSE) -> Female | D5: =VLOOKUP(A5, user_table!$A:$F, 5, FALSE) -> Desktop | E5: =VLOOKUP(A5, user_table!$A:$F, 6, FALSE) -> Paid | F5: =IF(ISNUMBER(MATCH(A5, search_page!$A:$A, 0)), "Yes", "No") -> Yes | H5: Grand Total | I5: 1000
A6: 1005 | B6: 45362.432 | C6: =VLOOKUP(A6, user_table!$A:$B, 2, FALSE) -> Male | D6: =VLOOKUP(A6, user_table!$A:$F, 5, FALSE) -> Desktop | E6: =VLOOKUP(A6, user_table!$A:$F, 6, FALSE) -> Email | F6: =IF(ISNUMBER(MATCH(A6, search_page!$A:$A, 0)), "Yes", "No") -> No
A7: 1006 | B7: 45381.595 | C7: =VLOOKUP(A7, user_table!$A:$B, 2, FALSE) -> Male | D7: =VLOOKUP(A7, user_table!$A:$F, 5, FALSE) -> Mobile | E7: =VLOOKUP(A7, user_table!$A:$F, 6, FALSE) -> Organic | F7: =IF(ISNUMBER(MATCH(A7, search_page!$A:$A, 0)), "Yes", "No") -> No | H7: Count of user_id | I7: Column Labels
A8: 1007 | B8: 45331.343 | C8: =VLOOKUP(A8, user_table!$A:$B, 2, FALSE) -> Male | D8: =VLOOKUP(A8, user_table!$A:$F, 5, FALSE) -> Mobile | E8: =VLOOKUP(A8, user_table!$A:$F, 6, FALSE) -> Organic | F8: =IF(ISNUMBER(MATCH(A8, search_page!$A:$A, 0)), "Yes", "No") -> Yes | I8: Desktop | J8: Mobile | K8: Tablet | L8: Grand Total
A9: 1008 | B9: 45307.967 | C9: =VLOOKUP(A9, user_table!$A:$B, 2, FALSE) -> Female | D9: =VLOOKUP(A9, user_table!$A:$F, 5, FALSE) -> Desktop | E9: =VLOOKUP(A9, user_table!$A:$F, 6, FALSE) -> Paid | F9: =IF(ISNUMBER(MATCH(A9, search_page!$A:$A, 0)), "Yes", "No") -> Yes | H9: Row Labels
A10: 1009 | B10: 45332.158 | C10: =VLOOKUP(A10, user_table!$A:$B, 2, FALSE) -> Female | D10: =VLOOKUP(A10, user_table!$A:$F, 5, FALSE) -> Mobile | E10: =VLOOKUP(A10, user_table!$A:$F, 6, FALSE) -> Organic | F10: =IF(ISNUMBER(MATCH(A10, search_page!$A:$A, 0)), "Yes", "No") -> Yes | H10: Female | I10: 245 | J10: 172 | K10: 58 | L10: 475
A11: 1010 | B11: 45360.924 | C11: =VLOOKUP(A11, user_table!$A:$B, 2, FALSE) -> Female | D11: =VLOOKUP(A11, user_table!$A:$F, 5, FALSE) -> Desktop | E11: =VLOOKUP(A11, user_table!$A:$F, 6, FALSE) -> Organic | F11: =IF(ISNUMBER(MATCH(A11, search_page!$A:$A, 0)), "Yes", "No") -> Yes | H11: Male | I11: 254 | J11: 190 | K11: 81 | L11: 525
A12: 1011 | B12: 45316.283 | C12: =VLOOKUP(A12, user_table!$A:$B, 2, FALSE) -> Male | D12: =VLOOKUP(A12, user_table!$A:$F, 5, FALSE) -> Mobile | E12: =VLOOKUP(A12, user_table!$A:$F, 6, FALSE) -> Social | F12: =IF(ISNUMBER(MATCH(A12, search_page!$A:$A, 0)), "Yes", "No") -> No | H12: Grand Total | I12: 499 | J12: 362 | K12: 139 | L12: 1000
A13: 1012 | B13: 45353.365 | C13: =VLOOKUP(A13, user_table!$A:$B, 2, FALSE) -> Female | D13: =VLOOKUP(A13, user_table!$A:$F, 5, FALSE) -> Desktop | E13: =VLOOKUP(A13, user_table!$A:$F, 6, FALSE) -> Organic | F13: =IF(ISNUMBER(MATCH(A13, search_page!$A:$A, 0)), "Yes", "No") -> Yes
A14: 1013 | B14: 45367.693 | C14: =VLOOKUP(A14, user_table!$A:$B, 2, FALSE) -> Female | D14: =VLOOKUP(A14, user_table!$A:$F, 5, FALSE) -> Tablet | E14: =VLOOKUP(A14, user_table!$A:$F, 6, FALSE) -> Social | F14: =IF(ISNUMBER(MATCH(A14, search_page!$A:$A, 0)), "Yes", "No") -> Yes | H14: Count of user_id | I14: Column Labels
A15: 1014 | B15: 45328.162 | C15: =VLOOKUP(A15, user_table!$A:$B, 2, FALSE) -> Male | D15: =VLOOKUP(A15, user_table!$A:$F, 5, FALSE) -> Desktop | E15: =VLOOKUP(A15, user_table!$A:$F, 6, FALSE) -> Organic | F15: =IF(ISNUMBER(MATCH(A15, search_page!$A:$A, 0)), "Yes", "No") -> No | H15: Row Labels | I15: Direct | J15: Email | K15: Organic | L15: Paid | M15: Social | N15: Grand Total
A16: 1015 | B16: 45316.385 | C16: =VLOOKUP(A16, user_table!$A:$B, 2, FALSE) -> Male | D16: =VLOOKUP(A16, user_table!$A:$F, 5, FALSE) -> Desktop | E16: =VLOOKUP(A16, user_table!$A:$F, 6, FALSE) -> Organic | F16: =IF(ISNUMBER(MATCH(A16, search_page!$A:$A, 0)), "Yes", "No") -> Yes | H16: Desktop | I16: 41 | J16: 77 | K16: 149 | L16: 114 | M16: 118 | N16: 499
A17: 1016 | B17: 45338.222 | C17: =VLOOKUP(A17, user_table!$A:$B, 2, FALSE) -> Male | D17: =VLOOKUP(A17, user_table!$A:$F, 5, FALSE) -> Desktop | E17: =VLOOKUP(A17, user_table!$A:$F, 6, FALSE) -> Paid | F17: =IF(ISNUMBER(MATCH(A17, search_page!$A:$A, 0)), "Yes", "No") -> Yes | H17: Mobile | I17: 33 | J17: 50 | K17: 115 | L17: 89 | M17: 75 | N17: 362
A18: 1017 | B18: 45293.94 | C18: =VLOOKUP(A18, user_table!$A:$B, 2, FALSE) -> Male | D18: =VLOOKUP(A18, user_table!$A:$F, 5, FALSE) -> Desktop | E18: =VLOOKUP(A18, user_table!$A:$F, 6, FALSE) -> Email | F18: =IF(ISNUMBER(MATCH(A18, search_page!$A:$A, 0)), "Yes", "No") -> No | H18: Tablet | I18: 17 | J18: 17 | K18: 39 | L18: 41 | M18: 25 | N18: 139
A19: 1018 | B19: 45308.335 | C19: =VLOOKUP(A19, user_table!$A:$B, 2, FALSE) -> Female | D19: =VLOOKUP(A19, user_table!$A:$F, 5, FALSE) -> Mobile | E19: =VLOOKUP(A19, user_table!$A:$F, 6, FALSE) -> Paid | F19: =IF(ISNUMBER(MATCH(A19, search_page!$A:$A, 0)), "Yes", "No") -> No | H19: Grand Total | I19: 91 | J19: 144 | K19: 303 | L19: 244 | M19: 218 | N19: 1000
A20: 1019 | B20: 45298.721 | C20: =VLOOKUP(A20, user_table!$A:$B, 2, FALSE) -> Male | D20: =VLOOKUP(A20, user_table!$A:$F, 5, FALSE) -> Desktop | E20: =VLOOKUP(A20, user_table!$A:$F, 6, FALSE) -> Email | F20: =IF(ISNUMBER(MATCH(A20, search_page!$A:$A, 0)), "Yes", "No") -> No
A21: 1020 | B21: 45381.194 | C21: =VLOOKUP(A21, user_table!$A:$B, 2, FALSE) -> Male | D21: =VLOOKUP(A21, user_table!$A:$F, 5, FALSE) -> Mobile | E21: =VLOOKUP(A21, user_table!$A:$F, 6, FALSE) -> Organic | F21: =IF(ISNUMBER(MATCH(A21, search_page!$A:$A, 0)), "Yes", "No") -> Yes
A22: 1021 | B22: 45354.163 | C22: =VLOOKUP(A22, user_table!$A:$B, 2, FALSE) -> Female | D22: =VLOOKUP(A22, user_table!$A:$F, 5, FALSE) -> Desktop | E22: =VLOOKUP(A22, user_table!$A:$F, 6, FALSE) -> Email | F22: =IF(ISNUMBER(MATCH(A22, search_page!$A:$A, 0)), "Yes", "No") -> No
A23: 1022 | B23: 45293.762 | C23: =VLOOKUP(A23, user_table!$A:$B, 2, FALSE) -> Male | D23: =VLOOKUP(A23, user_table!$A:$F, 5, FALSE) -> Desktop | E23: =VLOOKUP(A23, user_table!$A:$F, 6, FALSE) -> Organic | F23: =IF(ISNUMBER(MATCH(A23, search_page!$A:$A, 0)), "Yes", "No") -> Yes
A24: 1023 | B24: 45352.644 | C24: =VLOOKUP(A24, user_table!$A:$B, 2, FALSE) -> Male | D24: =VLOOKUP(A24, user_table!$A:$F, 5, FALSE) -> Desktop | E24: =VLOOKUP(A24, user_table!$A:$F, 6, FALSE) -> Social | F24: =IF(ISNUMBER(MATCH(A24, search_page!$A:$A, 0)), "Yes", "No") -> Yes
A25: 1024 | B25: 45335.21 | C25: =VLOOKUP(A25, user_table!$A:$B, 2, FALSE) -> Male | D25: =VLOOKUP(A25, user_table!$A:$F, 5, FALSE) -> Desktop | E25: =VLOOKUP(A25, user_table!$A:$F, 6, FALSE) -> Social | F25: =IF(ISNUMBER(MATCH(A25, search_page!$A:$A, 0)), "Yes", "No") -> No
A26: 1025 | B26: 45324.63 | C26: =VLOOKUP(A26, user_table!$A:$B, 2, FALSE) -> Male | D26: =VLOOKUP(A26, user_table!$A:$F, 5, FALSE) -> Desktop | E26: =VLOOKUP(A26, user_table!$A:$F, 6, FALSE) -> Direct | F26: =IF(ISNUMBER(MATCH(A26, search_page!$A:$A, 0)), "Yes", "No") -> No
A27: 1026 | B27: 45300.522 | C27: =VLOOKUP(A27, user_table!$A:$B, 2, FALSE) -> Female | D27: =VLOOKUP(A27, user_table!$A:$F, 5, FALSE) -> Desktop | E27: =VLOOKUP(A27, user_table!$A:$F, 6, FALSE) -> Paid | F27: =IF(ISNUMBER(MATCH(A27, search_page!$A:$A, 0)), "Yes", "No") -> Yes
A28: 1027 | B28: 45301.778 | C28: =VLOOKUP(A28, user_table!$A:$B, 2, FALSE) -> Male | D28: =VLOOKUP(A28, user_table!$A:$F, 5, FALSE) -> Desktop | E28: =VLOOKUP(A28, user_table!$A:$F, 6, FALSE) -> Organic | F28: =IF(ISNUMBER(MATCH(A28, search_page!$A:$A, 0)), "Yes", "No") -> No
A29: 1028 | B29: 45379.048 | C29: =VLOOKUP(A29, user_table!$A:$B, 2, FALSE) -> Male | D29: =VLOOKUP(A29, user_table!$A:$F, 5, FALSE) -> Desktop | E29: =VLOOKUP(A29, user_table!$A:$F, 6, FALSE) -> Organic | F29: =IF(ISNUMBER(MATCH(A29, search_page!$A:$A, 0)), "Yes", "No") -> Yes
A30: 1029 | B30: 45311.763 | C30: =VLOOKUP(A30, user_table!$A:$B, 2, FALSE) -> Female | D30: =VLOOKUP(A30, user_table!$A:$F, 5, FALSE) -> Mobile | E30: =VLOOKUP(A30, user_table!$A:$F, 6, FALSE) -> Email | F30: =IF(ISNUMBER(MATCH(A30, search_page!$A:$A, 0)), "Yes", "No") -> No
A31: 1030 | B31: 45302.297 | C31: =VLOOKUP(A31, user_table!$A:$B, 2, FALSE) -> Male | D31: =VLOOKUP(A31, user_table!$A:$F, 5, FALSE) -> Mobile | E31: =VLOOKUP(A31, user_table!$A:$F, 6, FALSE) -> Paid | F31: =IF(ISNUMBER(MATCH(A31, search_page!$A:$A, 0)), "Yes", "No") -> No
... A1001: 2000 | B1001: 45375.197 | C1001: =VLOOKUP(A1001, user_table!$A:$B, 2, FALSE) -> Male | D1001: =VLOOKUP(A1001, user_table!$A:$F, 5, FALSE) -> Mobile | E1001: =VLOOKUP(A1001, user_table!$A:$F, 6, FALSE) -> Social | F1001: =IF(ISNUMBER(MATCH(A1001, search_page!$A:$A, 0)), "Yes", "No") -> Yes

Sheet search_page
A1: user_id | B1: timestamp | C1: Gender | D1: Device | E1: Traffic Source
A2: 1655 | B2: 45309.298 | C2: =VLOOKUP(A2, user_table!$A:$B, 2, FALSE) -> Male | D2: =VLOOKUP(A2, user_table!$A:$F, 5, FALSE) -> Desktop | E2: =VLOOKUP(A2, user_table!$A:$F, 6, FALSE) -> Social | G2: Count of user_id | H2: Column Labels
A3: 1115 | B3: 45334.325 | C3: =VLOOKUP(A3, user_table!$A:$B, 2, FALSE) -> Female | D3: =VLOOKUP(A3, user_table!$A:$F, 5, FALSE) -> Desktop | E3: =VLOOKUP(A3, user_table!$A:$F, 6, FALSE) -> Email | G3: Row Labels | H3: Female | I3: Male | J3: Grand Total
A4: 1026 | B4: 45379.522 | C4: =VLOOKUP(A4, user_table!$A:$B, 2, FALSE) -> Female | D4: =VLOOKUP(A4, user_table!$A:$F, 5, FALSE) -> Desktop | E4: =VLOOKUP(A4, user_table!$A:$F, 6, FALSE) -> Paid | G4: Desktop | H4: 134 | I4: 139 | J4: 273
A5: 1760 | B5: 45311.778 | C5: =VLOOKUP(A5, user_table!$A:$B, 2, FALSE) -> Female | D5: =VLOOKUP(A5, user_table!$A:$F, 5, FALSE) -> Mobile | E5: =VLOOKUP(A5, user_table!$A:$F, 6, FALSE) -> Direct | G5: Direct | H5: 14 | I5: 8 | J5: 22
A6: 1282 | B6: 45327.851 | C6: =VLOOKUP(A6, user_table!$A:$B, 2, FALSE) -> Male | D6: =VLOOKUP(A6, user_table!$A:$F, 5, FALSE) -> Mobile | E6: =VLOOKUP(A6, user_table!$A:$F, 6, FALSE) -> Paid | G6: Email | H6: 24 | I6: 15 | J6: 39
A7: 1251 | B7: 45341.586 | C7: =VLOOKUP(A7, user_table!$A:$B, 2, FALSE) -> Male | D7: =VLOOKUP(A7, user_table!$A:$F, 5, FALSE) -> Mobile | E7: =VLOOKUP(A7, user_table!$A:$F, 6, FALSE) -> Organic | G7: Organic | H7: 37 | I7: 44 | J7: 81
A8: 1229 | B8: 45374.101 | C8: =VLOOKUP(A8, user_table!$A:$B, 2, FALSE) -> Female | D8: =VLOOKUP(A8, user_table!$A:$F, 5, FALSE) -> Desktop | E8: =VLOOKUP(A8, user_table!$A:$F, 6, FALSE) -> Email | G8: Paid | H8: 32 | I8: 34 | J8: 66
A9: 1143 | B9: 45358.97 | C9: =VLOOKUP(A9, user_table!$A:$B, 2, FALSE) -> Male | D9: =VLOOKUP(A9, user_table!$A:$F, 5, FALSE) -> Mobile | E9: =VLOOKUP(A9, user_table!$A:$F, 6, FALSE) -> Organic | G9: Social | H9: 27 | I9: 38 | J9: 65
A10: 1755 | B10: 45381.478 | C10: =VLOOKUP(A10, user_table!$A:$B, 2, FALSE) -> Male | D10: =VLOOKUP(A10, user_table!$A:$F, 5, FALSE) -> Desktop | E10: =VLOOKUP(A10, user_table!$A:$F, 6, FALSE) -> Paid | G10: Mobile | H10: 93 | I10: 111 | J10: 204
A11: 1105 | B11: 45355.442 | C11: =VLOOKUP(A11, user_table!$A:$B, 2, FALSE) -> Female | D11: =VLOOKUP(A11, user_table!$A:$F, 5, FALSE) -> Mobile | E11: =VLOOKUP(A11, user_table!$A:$F, 6, FALSE) -> Social | G11: Direct | H11: 5 | I11: 11 | J11: 16
A12: 1693 | B12: 45293.962 | C12: =VLOOKUP(A12, user_table!$A:$B, 2, FALSE) -> Male | D12: =VLOOKUP(A12, user_table!$A:$F, 5, FALSE) -> Desktop | E12: =VLOOKUP(A12, user_table!$A:$F, 6, FALSE) -> Paid | G12: Email | H12: 17 | I12: 13 | J12: 30
A13: 1759 | B13: 45351.863 | C13: =VLOOKUP(A13, user_table!$A:$B, 2, FALSE) -> Female | D13: =VLOOKUP(A13, user_table!$A:$F, 5, FALSE) -> Mobile | E13: =VLOOKUP(A13, user_table!$A:$F, 6, FALSE) -> Organic | G13: Organic | H13: 30 | I13: 39 | J13: 69
A14: 1914 | B14: 45382.496 | C14: =VLOOKUP(A14, user_table!$A:$B, 2, FALSE) -> Male | D14: =VLOOKUP(A14, user_table!$A:$F, 5, FALSE) -> Desktop | E14: =VLOOKUP(A14, user_table!$A:$F, 6, FALSE) -> Paid | G14: Paid | H14: 23 | I14: 22 | J14: 45
A15: 1559 | B15: 45301.726 | C15: =VLOOKUP(A15, user_table!$A:$B, 2, FALSE) -> Female | D15: =VLOOKUP(A15, user_table!$A:$F, 5, FALSE) -> Mobile | E15: =VLOOKUP(A15, user_table!$A:$F, 6, FALSE) -> Paid | G15: Social | H15: 18 | I15: 26 | J15: 44
... A22: 1224 | B22: 45299.046 | C22: =VLOOKUP(A22, user_table!$A:$B, 2, FALSE) -> Male | D22: =VLOOKUP(A22, user_table!$A:$F, 5, FALSE) -> Tablet | E22: =VLOOKUP(A22, user_table!$A:$F, 6, FALSE) -> Direct | G22: Grand Total | H22: 255 | I22: 295 | J22: 550
A23: 1239 | B23: 45373.584 | C23: =VLOOKUP(A23, user_table!$A:$B, 2, FALSE) -> Female | D23: =VLOOKUP(A23, user_table!$A:$F, 5, FALSE) -> Desktop | E23: =VLOOKUP(A23, user_table!$A:$F, 6, FALSE) -> Paid
A24: 1518 | B24: 45308.228 | C24: =VLOOKUP(A24, user_table!$A:$B, 2, FALSE) -> Female | D24: =VLOOKUP(A24, user_table!$A:$F, 5, FALSE) -> Mobile | E24: =VLOOKUP(A24, user_table!$A:$F, 6, FALSE) -> Paid
A25: 1617 | B25: 45351.019 | C25: =VLOOKUP(A25, user_table!$A:$B, 2, FALSE) -> Male | D25: =VLOOKUP(A25, user_table!$A:$F, 5, FALSE) -> Desktop | E25: =VLOOKUP(A25, user_table!$A:$F, 6, FALSE) -> Organic
A26: 1028 | B26: 45318.957 | C26: =VLOOKUP(A26, user_table!$A:$B, 2, FALSE) -> Male | D26: =VLOOKUP(A26, user_table!$A:$F, 5, FALSE) -> Desktop | E26: =VLOOKUP(A26, user_table!$A:$F, 6, FALSE) -> Organic
A27: 1575 | B27: 45309.847 | C27: =VLOOKUP(A27, user_table!$A:$B, 2, FALSE) -> Female | D27: =VLOOKUP(A27, user_table!$A:$F, 5, FALSE) -> Desktop | E27: =VLOOKUP(A27, user_table!$A:$F, 6, FALSE) -> Organic
A28: 1204 | B28: 45313.337 | C28: =VLOOKUP(A28, user_table!$A:$B, 2, FALSE) -> Female | D28: =VLOOKUP(A28, user_table!$A:$F, 5, FALSE) -> Mobile | E28: =VLOOKUP(A28, user_table!$A:$F, 6, FALSE) -> Paid
A29: 1734 | B29: 45376.469 | C29: =VLOOKUP(A29, user_table!$A:$B, 2, FALSE) -> Female | D29: =VLOOKUP(A29, user_table!$A:$F, 5, FALSE) -> Tablet | E29: =VLOOKUP(A29, user_table!$A:$F, 6, FALSE) -> Email
A30: 1666 | B30: 45303.488 | C30: =VLOOKUP(A30, user_table!$A:$B, 2, FALSE) -> Male | D30: =VLOOKUP(A30, user_table!$A:$F, 5, FALSE) -> Mobile | E30: =VLOOKUP(A30, user_table!$A:$F, 6, FALSE) -> Direct
A31: 1719 | B31: 45376.21 | C31: =VLOOKUP(A31, user_table!$A:$B, 2, FALSE) -> Male | D31: =VLOOKUP(A31, user_table!$A:$F, 5, FALSE) -> Desktop | E31: =VLOOKUP(A31, user_table!$A:$F, 6, FALSE) -> Organic
A32: 1987 | B32: 45343.847 | C32: =VLOOKUP(A32, user_table!$A:$B, 2, FALSE) -> Female | D32: =VLOOKUP(A32, user_table!$A:$F, 5, FALSE) -> Mobile | E32: =VLOOKUP(A32, user_table!$A:$F, 6, FALSE) -> Email
A33: 1430 | B33: 45382.31 | C33: =VLOOKUP(A33, user_table!$A:$B, 2, FALSE) -> Male | D33: =VLOOKUP(A33, user_table!$A:$F, 5, FALSE) -> Tablet | E33: =VLOOKUP(A33, user_table!$A:$F, 6, FALSE) -> Paid
A34: 1226 | B34: 45376.115 | C34: =VLOOKUP(A34, user_table!$A:$B, 2, FALSE) -> Male | D34: =VLOOKUP(A34, user_table!$A:$F, 5, FALSE) -> Desktop | E34: =VLOOKUP(A34, user_table!$A:$F, 6, FALSE) -> Social
... A551: 1344 | B551: 45351.281 | C551: =VLOOKUP(A551, user_table!$A:$B, 2, FALSE) -> Male | D551: =VLOOKUP(A551, user_table!$A:$F, 5, FALSE) -> Mobile | E551: =VLOOKUP(A551, user_table!$A:$F, 6, FALSE) -> Organic

Sheet confirmation_page
A1: user_id | B1: timestamp | C1: Gender | D1: Device | E1: Traffic Source
A2: 1855 | B2: 45323.568 | C2: =VLOOKUP(A2, user_table!$A:$B, 2, FALSE) -> Male | D2: =VLOOKUP(A2, user_table!$A:$F, 5, FALSE) -> Desktop | E2: =VLOOKUP(A2, user_table!$A:$F, 6, FALSE) -> Paid | G2: Count of user_id | H2: Column Labels
A3: 1166 | B3: 45313.786 | C3: =VLOOKUP(A3, user_table!$A:$B, 2, FALSE) -> Female | D3: =VLOOKUP(A3, user_table!$A:$F, 5, FALSE) -> Desktop | E3: =VLOOKUP(A3, user_table!$A:$F, 6, FALSE) -> Paid | G3: Row Labels | H3: Female | I3: Male | J3: Grand Total
A4: 1009 | B4: 45318.821 | C4: =VLOOKUP(A4, user_table!$A:$B, 2, FALSE) -> Female | D4: =VLOOKUP(A4, user_table!$A:$F, 5, FALSE) -> Mobile | E4: =VLOOKUP(A4, user_table!$A:$F, 6, FALSE) -> Organic | G4: Desktop | H4: 32 | I4: 31 | J4: 63
A5: 1630 | B5: 45360.34 | C5: =VLOOKUP(A5, user_table!$A:$B, 2, FALSE) -> Male | D5: =VLOOKUP(A5, user_table!$A:$F, 5, FALSE) -> Tablet | E5: =VLOOKUP(A5, user_table!$A:$F, 6, FALSE) -> Organic | G5: Direct | H5: 3 | J5: 3
A6: 1101 | B6: 45382.458 | C6: =VLOOKUP(A6, user_table!$A:$B, 2, FALSE) -> Male | D6: =VLOOKUP(A6, user_table!$A:$F, 5, FALSE) -> Mobile | E6: =VLOOKUP(A6, user_table!$A:$F, 6, FALSE) -> Paid | G6: Email | H6: 5 | I6: 2 | J6: 7
A7: 1058 | B7: 45353.817 | C7: =VLOOKUP(A7, user_table!$A:$B, 2, FALSE) -> Male | D7: =VLOOKUP(A7, user_table!$A:$F, 5, FALSE) -> Desktop | E7: =VLOOKUP(A7, user_table!$A:$F, 6, FALSE) -> Organic | G7: Organic | H7: 11 | I7: 11 | J7: 22
A8: 1891 | B8: 45303.308 | C8: =VLOOKUP(A8, user_table!$A:$B, 2, FALSE) -> Female | D8: =VLOOKUP(A8, user_table!$A:$F, 5, FALSE) -> Mobile | E8: =VLOOKUP(A8, user_table!$A:$F, 6, FALSE) -> Organic | G8: Paid | H8: 8 | I8: 6 | J8: 14
A9: 1913 | B9: 45344.171 | C9: =VLOOKUP(A9, user_table!$A:$B, 2, FALSE) -> Female | D9: =VLOOKUP(A9, user_table!$A:$F, 5, FALSE) -> Tablet | E9: =VLOOKUP(A9, user_table!$A:$F, 6, FALSE) -> Email | G9: Social | H9: 5 | I9: 12 | J9: 17
A10: 1162 | B10: 45297.273 | C10: =VLOOKUP(A10, user_table!$A:$B, 2, FALSE) -> Female | D10: =VLOOKUP(A10, user_table!$A:$F, 5, FALSE) -> Desktop | E10: =VLOOKUP(A10, user_table!$A:$F, 6, FALSE) -> Paid | G10: Mobile | H10: 17 | I10: 25 | J10: 42
A11: 1656 | B11: 45359.893 | C11: =VLOOKUP(A11, user_table!$A:$B, 2, FALSE) -> Male | D11: =VLOOKUP(A11, user_table!$A:$F, 5, FALSE) -> Desktop | E11: =VLOOKUP(A11, user_table!$A:$F, 6, FALSE) -> Organic | G11: Direct | H11: 1 | I11: 3 | J11: 4
A12: 1688 | B12: 45314.796 | C12: =VLOOKUP(A12, user_table!$A:$B, 2, FALSE) -> Male | D12: =VLOOKUP(A12, user_table!$A:$F, 5, FALSE) -> Desktop | E12: =VLOOKUP(A12, user_table!$A:$F, 6, FALSE) -> Social | G12: Email | H12: 4 | I12: 4 | J12: 8
A13: 1395 | B13: 45317.665 | C13: =VLOOKUP(A13, user_table!$A:$B, 2, FALSE) -> Male | D13: =VLOOKUP(A13, user_table!$A:$F, 5, FALSE) -> Mobile | E13: =VLOOKUP(A13, user_table!$A:$F, 6, FALSE) -> Email | G13: Organic | H13: 6 | I13: 6 | J13: 12
A14: 1718 | B14: 45373.793 | C14: =VLOOKUP(A14, user_table!$A:$B, 2, FALSE) -> Female | D14: =VLOOKUP(A14, user_table!$A:$F, 5, FALSE) -> Mobile | E14: =VLOOKUP(A14, user_table!$A:$F, 6, FALSE) -> Paid | G14: Paid | H14: 3 | I14: 4 | J14: 7
A15: 1998 | B15: 45363.7 | C15: =VLOOKUP(A15, user_table!$A:$B, 2, FALSE) -> Male | D15: =VLOOKUP(A15, user_table!$A:$F, 5, FALSE) -> Tablet | E15: =VLOOKUP(A15, user_table!$A:$F, 6, FALSE) -> Social | G15: Social | H15: 3 | I15: 8 | J15: 11
A16: 1779 | B16: 45310.104 | C16: =VLOOKUP(A16, user_table!$A:$B, 2, FALSE) -> Female | D16: =VLOOKUP(A16, user_table!$A:$F, 5, FALSE) -> Desktop | E16: =VLOOKUP(A16, user_table!$A:$F, 6, FALSE) -> Email | G16: Tablet | H16: 9 | I16: 7 | J16: 16
A17: 1797 | B17: 45379.206 | C17: =VLOOKUP(A17, user_table!$A:$B, 2, FALSE) -> Female | D17: =VLOOKUP(A17, user_table!$A:$F, 5, FALSE) -> Mobile | E17: =VLOOKUP(A17, user_table!$A:$F, 6, FALSE) -> Paid | G17: Direct | H17: 1 | J17: 1
A18: 1256 | B18: 45372.744 | C18: =VLOOKUP(A18, user_table!$A:$B, 2, FALSE) -> Female | D18: =VLOOKUP(A18, user_table!$A:$F, 5, FALSE) -> Mobile | E18: =VLOOKUP(A18, user_table!$A:$F, 6, FALSE) -> Paid | G18: Email | H18: 1 | J18: 1
A19: 1568 | B19: 45295.903 | C19: =VLOOKUP(A19, user_table!$A:$B, 2, FALSE) -> Male | D19: =VLOOKUP(A19, user_table!$A:$F, 5, FALSE) -> Desktop | E19: =VLOOKUP(A19, user_table!$A:$F, 6, FALSE) -> Organic | G19: Organic | H19: 5 | I19: 4 | J19: 9
A20: 1066 | B20: 45350.685 | C20: =VLOOKUP(A20, user_table!$A:$B, 2, FALSE) -> Female | D20: =VLOOKUP(A20, user_table!$A:$F, 5, FALSE) -> Desktop | E20: =VLOOKUP(A20, user_table!$A:$F, 6, FALSE) -> Organic | G20: Paid | I20: 1 | J20: 1
A21: 1716 | B21: 45342.072 | C21: =VLOOKUP(A21, user_table!$A:$B, 2, FALSE) -> Female | D21: =VLOOKUP(A21, user_table!$A:$F, 5, FALSE) -> Desktop | E21: =VLOOKUP(A21, user_table!$A:$F, 6, FALSE) -> Email | G21: Social | H21: 2 | I21: 2 | J21: 4
A22: 1332 | B22: 45362.551 | C22: =VLOOKUP(A22, user_table!$A:$B, 2, FALSE) -> Female | D22: =VLOOKUP(A22, user_table!$A:$F, 5, FALSE) -> Desktop | E22: =VLOOKUP(A22, user_table!$A:$F, 6, FALSE) -> Organic | G22: Grand Total | H22: 58 | I22: 63 | J22: 121
A23: 1690 | B23: 45356.515 | C23: =VLOOKUP(A23, user_table!$A:$B, 2, FALSE) -> Male | D23: =VLOOKUP(A23, user_table!$A:$F, 5, FALSE) -> Desktop | E23: =VLOOKUP(A23, user_table!$A:$F, 6, FALSE) -> Social
A24: 1592 | B24: 45370.999 | C24: =VLOOKUP(A24, user_table!$A:$B, 2, FALSE) -> Female | D24: =VLOOKUP(A24, user_table!$A:$F, 5, FALSE) -> Desktop | E24: =VLOOKUP(A24, user_table!$A:$F, 6, FALSE) -> Paid
A25: 1905 | B25: 45384.754 | C25: =VLOOKUP(A25, user_table!$A:$B, 2, FALSE) -> Male | D25: =VLOOKUP(A25, user_table!$A:$F, 5, FALSE) -> Mobile | E25: =VLOOKUP(A25, user_table!$A:$F, 6, FALSE) -> Organic
A26: 1285 | B26: 45349.178 | C26: =VLOOKUP(A26, user_table!$A:$B, 2, FALSE) -> Female | D26: =VLOOKUP(A26, user_table!$A:$F, 5, FALSE) -> Mobile | E26: =VLOOKUP(A26, user_table!$A:$F, 6, FALSE) -> Social
A27: 1585 | B27: 45356.332 | C27: =VLOOKUP(A27, user_table!$A:$B, 2, FALSE) -> Female | D27: =VLOOKUP(A27, user_table!$A:$F, 5, FALSE) -> Mobile | E27: =VLOOKUP(A27, user_table!$A:$F, 6, FALSE) -> Organic
A28: 1082 | B28: 45305.401 | C28: =VLOOKUP(A28, user_table!$A:$B, 2, FALSE) -> Female | D28: =VLOOKUP(A28, user_table!$A:$F, 5, FALSE) -> Desktop | E28: =VLOOKUP(A28, user_table!$A:$F, 6, FALSE) -> Organic
A29: 1498 | B29: 45364.553 | C29: =VLOOKUP(A29, user_table!$A:$B, 2, FALSE) -> Male | D29: =VLOOKUP(A29, user_table!$A:$F, 5, FALSE) -> Desktop | E29: =VLOOKUP(A29, user_table!$A:$F, 6, FALSE) -> Social
A30: 1971 | B30: 45319.031 | C30: =VLOOKUP(A30, user_table!$A:$B, 2, FALSE) -> Female | D30: =VLOOKUP(A30, user_table!$A:$F, 5, FALSE) -> Desktop | E30: =VLOOKUP(A30, user_table!$A:$F, 6, FALSE) -> Email
A31: 1408 | B31: 45295.773 | C31: =VLOOKUP(A31, user_table!$A:$B, 2, FALSE) -> Male | D31: =VLOOKUP(A31, user_table!$A:$F, 5, FALSE) -> Mobile | E31: =VLOOKUP(A31, user_table!$A:$F, 6, FALSE) -> Email
A32: 1422 | B32: 45310.667 | C32: =VLOOKUP(A32, user_table!$A:$B, 2, FALSE) -> Female | D32: =VLOOKUP(A32, user_table!$A:$F, 5, FALSE) -> Mobile | E32: =VLOOKUP(A32, user_table!$A:$F, 6, FALSE) -> Social
A33: 1621 | B33: 45343.842 | C33: =VLOOKUP(A33, user_table!$A:$B, 2, FALSE) -> Male | D33: =VLOOKUP(A33, user_table!$A:$F, 5, FALSE) -> Tablet | E33: =VLOOKUP(A33, user_table!$A:$F, 6, FALSE) -> Organic
A34: 1983 | B34: 45383.435 | C34: =VLOOKUP(A34, user_table!$A:$B, 2, FALSE) -> Male | D34: =VLOOKUP(A34, user_table!$A:$F, 5, FALSE) -> Mobile | E34: =VLOOKUP(A34, user_table!$A:$F, 6, FALSE) -> Social
... A122: 1153 | B122: 45339.538 | C122: =VLOOKUP(A122, user_table!$A:$B, 2, FALSE) -> Male | D122: =VLOOKUP(A122, user_table!$A:$F, 5, FALSE) -> Mobile | E122: =VLOOKUP(A122, user_table!$A:$F, 6, FALSE) -> Organic

Sheet payment_page
A1: user_id | B1: timestamp | C1: Gender | D1: Device | E1: Traffic Source
A2: 1781 | B2: 45337.158 | C2: =VLOOKUP(A2, user_table!$A:$B, 2, FALSE) -> Female | D2: =VLOOKUP(A2, user_table!$A:$F, 5, FALSE) -> Desktop | E2: =VLOOKUP(A2, user_table!$A:$F, 6, FALSE) -> Organic | G2: Count of user_id | H2: Column Labels
A3: 1724 | B3: 45347.083 | C3: =VLOOKUP(A3, user_table!$A:$B, 2, FALSE) -> Female | D3: =VLOOKUP(A3, user_table!$A:$F, 5, FALSE) -> Tablet | E3: =VLOOKUP(A3, user_table!$A:$F, 6, FALSE) -> Social | H3: Direct | I3: Email | J3: Organic | K3: Paid | L3: Social | M3: Grand Total
A4: 1046 | B4: 45375.901 | C4: =VLOOKUP(A4, user_table!$A:$B, 2, FALSE) -> Female | D4: =VLOOKUP(A4, user_table!$A:$F, 5, FALSE) -> Desktop | E4: =VLOOKUP(A4, user_table!$A:$F, 6, FALSE) -> Organic | G4: Row Labels
A5: 1634 | B5: 45309.603 | C5: =VLOOKUP(A5, user_table!$A:$B, 2, FALSE) -> Female | D5: =VLOOKUP(A5, user_table!$A:$F, 5, FALSE) -> Desktop | E5: =VLOOKUP(A5, user_table!$A:$F, 6, FALSE) -> Organic | G5: Female | H5: 11 | I5: 18 | J5: 35 | K5: 20 | L5: 16 | M5: 100
A6: 1870 | B6: 45378.772 | C6: =VLOOKUP(A6, user_table!$A:$B, 2, FALSE) -> Female | D6: =VLOOKUP(A6, user_table!$A:$F, 5, FALSE) -> Mobile | E6: =VLOOKUP(A6, user_table!$A:$F, 6, FALSE) -> Organic | G6: Male | H6: 10 | I6: 12 | J6: 37 | K6: 28 | L6: 33 | M6: 120
A7: 1913 | B7: 45311.625 | C7: =VLOOKUP(A7, user_table!$A:$B, 2, FALSE) -> Female | D7: =VLOOKUP(A7, user_table!$A:$F, 5, FALSE) -> Tablet | E7: =VLOOKUP(A7, user_table!$A:$F, 6, FALSE) -> Email | G7: Grand Total | H7: 21 | I7: 30 | J7: 72 | K7: 48 | L7: 49 | M7: 220
A8: 1983 | B8: 45361.96 | C8: =VLOOKUP(A8, user_table!$A:$B, 2, FALSE) -> Male | D8: =VLOOKUP(A8, user_table!$A:$F, 5, FALSE) -> Mobile | E8: =VLOOKUP(A8, user_table!$A:$F, 6, FALSE) -> Social
A9: 1101 | B9: 45364.578 | C9: =VLOOKUP(A9, user_table!$A:$B, 2, FALSE) -> Male | D9: =VLOOKUP(A9, user_table!$A:$F, 5, FALSE) -> Mobile | E9: =VLOOKUP(A9, user_table!$A:$F, 6, FALSE) -> Paid | G9: Count of user_id | H9: Column Labels
A10: 1298 | B10: 45368.666 | C10: =VLOOKUP(A10, user_table!$A:$B, 2, FALSE) -> Male | D10: =VLOOKUP(A10, user_table!$A:$F, 5, FALSE) -> Mobile | E10: =VLOOKUP(A10, user_table!$A:$F, 6, FALSE) -> Organic | G10: Row Labels | H10: Female | I10: Male | J10: Grand Total
A11: 1967 | B11: 45359.239 | C11: =VLOOKUP(A11, user_table!$A:$B, 2, FALSE) -> Female | D11: =VLOOKUP(A11, user_table!$A:$F, 5, FALSE) -> Mobile | E11: =VLOOKUP(A11, user_table!$A:$F, 6, FALSE) -> Social | G11: Desktop | H11: 50 | I11: 62 | J11: 112
A12: 1009 | B12: 45368.24 | C12: =VLOOKUP(A12, user_table!$A:$B, 2, FALSE) -> Female | D12: =VLOOKUP(A12, user_table!$A:$F, 5, FALSE) -> Mobile | E12: =VLOOKUP(A12, user_table!$A:$F, 6, FALSE) -> Organic | G12: Mobile | H12: 36 | I12: 42 | J12: 78
A13: 1752 | B13: 45310.142 | C13: =VLOOKUP(A13, user_table!$A:$B, 2, FALSE) -> Female | D13: =VLOOKUP(A13, user_table!$A:$F, 5, FALSE) -> Desktop | E13: =VLOOKUP(A13, user_table!$A:$F, 6, FALSE) -> Social | G13: Tablet | H13: 14 | I13: 16 | J13: 30
A14: 1292 | B14: 45378.818 | C14: =VLOOKUP(A14, user_table!$A:$B, 2, FALSE) -> Male | D14: =VLOOKUP(A14, user_table!$A:$F, 5, FALSE) -> Desktop | E14: =VLOOKUP(A14, user_table!$A:$F, 6, FALSE) -> Organic | G14: Grand Total | H14: 100 | I14: 120 | J14: 220
A15: 1479 | B15: 45335.706 | C15: =VLOOKUP(A15, user_table!$A:$B, 2, FALSE) -> Female | D15: =VLOOKUP(A15, user_table!$A:$F, 5, FALSE) -> Desktop | E15: =VLOOKUP(A15, user_table!$A:$F, 6, FALSE) -> Paid
A16: 1411 | B16: 45343.568 | C16: =VLOOKUP(A16, user_table!$A:$B, 2, FALSE) -> Male | D16: =VLOOKUP(A16, user_table!$A:$F, 5, FALSE) -> Desktop | E16: =VLOOKUP(A16, user_table!$A:$F, 6, FALSE) -> Social
A17: 1004 | B17: 45382.303 | C17: =VLOOKUP(A17, user_table!$A:$B, 2, FALSE) -> Female | D17: =VLOOKUP(A17, user_table!$A:$F, 5, FALSE) -> Desktop | E17: =VLOOKUP(A17, user_table!$A:$F, 6, FALSE) -> Paid
A18: 1216 | B18: 45344.429 | C18: =VLOOKUP(A18, user_table!$A:$B, 2, FALSE) -> Male | D18: =VLOOKUP(A18, user_table!$A:$F, 5, FALSE) -> Desktop | E18: =VLOOKUP(A18, user_table!$A:$F, 6, FALSE) -> Email
A19: 1210 | B19: 45351.172 | C19: =VLOOKUP(A19, user_table!$A:$B, 2, FALSE) -> Male | D19: =VLOOKUP(A19, user_table!$A:$F, 5, FALSE) -> Tablet | E19: =VLOOKUP(A19, user_table!$A:$F, 6, FALSE) -> Organic
A20: 1258 | B20: 45346.822 | C20: =VLOOKUP(A20, user_table!$A:$B, 2, FALSE) -> Female | D20: =VLOOKUP(A20, user_table!$A:$F, 5, FALSE) -> Desktop | E20: =VLOOKUP(A20, user_table!$A:$F, 6, FALSE) -> Email
A21: 1063 | B21: 45359.412 | C21: =VLOOKUP(A21, user_table!$A:$B, 2, FALSE) -> Female | D21: =VLOOKUP(A21, user_table!$A:$F, 5, FALSE) -> Desktop | E21: =VLOOKUP(A21, user_table!$A:$F, 6, FALSE) -> Paid
A22: 1557 | B22: 45383.747 | C22: =VLOOKUP(A22, user_table!$A:$B, 2, FALSE) -> Male | D22: =VLOOKUP(A22, user_table!$A:$F, 5, FALSE) -> Mobile | E22: =VLOOKUP(A22, user_table!$A:$F, 6, FALSE) -> Social
A23: 1655 | B23: 45334.949 | C23: =VLOOKUP(A23, user_table!$A:$B, 2, FALSE) -> Male | D23: =VLOOKUP(A23, user_table!$A:$F, 5, FALSE) -> Desktop | E23: =VLOOKUP(A23, user_table!$A:$F, 6, FALSE) -> Social
A24: 1112 | B24: 45364.842 | C24: =VLOOKUP(A24, user_table!$A:$B, 2, FALSE) -> Male | D24: =VLOOKUP(A24, user_table!$A:$F, 5, FALSE) -> Desktop | E24: =VLOOKUP(A24, user_table!$A:$F, 6, FALSE) -> Social
A25: 1417 | B25: 45319.277 | C25: =VLOOKUP(A25, user_table!$A:$B, 2, FALSE) -> Male | D25: =VLOOKUP(A25, user_table!$A:$F, 5, FALSE) -> Desktop | E25: =VLOOKUP(A25, user_table!$A:$F, 6, FALSE) -> Email
A26: 1553 | B26: 45331.89 | C26: =VLOOKUP(A26, user_table!$A:$B, 2, FALSE) -> Female | D26: =VLOOKUP(A26, user_table!$A:$F, 5, FALSE) -> Desktop | E26: =VLOOKUP(A26, user_table!$A:$F, 6, FALSE) -> Social
... A221: 1285 | B221: 45354.632 | C221: =VLOOKUP(A221, user_table!$A:$B, 2, FALSE) -> Female | D221: =VLOOKUP(A221, user_table!$A:$F, 5, FALSE) -> Mobile | E221: =VLOOKUP(A221, user_table!$A:$F, 6, FALSE) -> Social

Sheet Funnel Summary
A1: Step | B1: Users | C1: Step Conversion Rate | D1: Drop Rate | E1: Overall Conv
A2: Home Page | B2: =COUNTA(home_page!A:A)-1 -> 1000 | C2: 1 | D2: 0 | E2: 1 | H2: Gender | I2: Home | J2: Search | K2: Confirmation | L2: Payment | N2: From the Funnel Summary
A3: Search Page | B3: =COUNTA(search_page!A:A)-1 -> 550 | C3: =B3/B2 -> 0.55 | D3: =1-C3 -> 0.45 | E3: =B3/$B$2 -> 0.55 | H3: Male | I3: 525 | J3: 295 | K3: 63 | L3: 120
A4: Payment Page | B4: =COUNTA(payment_page!A:A)-1 -> 220 | C4: =B4/B3 -> 0.4 | D4: =1-C4 -> 0.6 | E4: =B4/$B$2 -> 0.22 | H4: Female | I4: 475 | J4: 255 | K4: 58 | L4: 100 | N4: The biggest drop-off is Home → Search (45% lost)
A5: Confirmation Page | B5: =COUNTA('confirmation_page'!A:A)-1 -> 121 | C5: =B5/B4 -> 0.55 | D5: =1-C5 -> 0.45 | E5: =B5/$B$2 -> 0.121
H6: Device | I6: Home | J6: Search | K6: Confirmation | L6: Payment | N6: Only 550 out of 1000 visitors even bothered to search/browse products
H7: Desktop | I7: 499 | J7: 273 | K7: 63 | L7: 112 | N7: This suggests your landing page isn't engaging enough — weak CTAs, slow load time, or wrong audience being targeted
H8: Mobile | I8: 362 | J8: 204 | K8: 42 | L8: 78
H9: Tablet | I9: 139 | J9: 73 | K9: 16 | L9: 30 | N9: Payment → Confirmation is also 45% drop-off
H11: Traffic Source | I11: Home | J11: Search | K11: Confirmation | L11: Payment | N11: 99 people started payment but didn't complete it
H12: Direct | I12: 91 | J12: 46 | K12: 8 | L12: 21 | N12: Classic cart abandonment — likely caused by unexpected costs (shipping/taxes), too many form fields, or lack of trust signals (no SSL badge, no reviews)
H13: Email | I13: 144 | J13: 76 | K13: 16 | L13: 30
H14: Paid | I14: 244 | J14: 136 | K14: 22 | L14: 48 | N14: Overall only 12% of visitors convert
H15: Social | I15: 218 | J15: 125 | K15: 32 | L15: 49
H16: Organic | I16: 303 | J16: 167 | K16: 43 | L16: 72 | N16: For every 100 visitors, only 12 actually buy — this is fairly typical for e-commerce (industry average is 2–4%), so 12% is actually decent here
N20: 👥 From the Gender Breakdown
O22: Home → Confirmation Conv.
N23: Male | O23: 63/525 = 12%
N24: Female | O24: 58/475 = 12.2%
N26: Gender makes virtually no difference in conversion
N27: No need to change messaging or targeting based on gender
N31: 💻 From the Device Breakdown
O33: Home → Confirmation Conv.
N34: Desktop | O34: 63/499 = 12.6%
N35: Mobile | O35: 42/362 = 11.6%
N36: Tablet | O36: 16/139 = 11.5%
N38: Desktop converts slightly better but the gap is small
N39: Mobile and Tablet are close behind — your site is reasonably mobile-friendly
N40: However, check the Payment → Confirmation drop on mobile specifically — mobile users often abandon at payment due to difficult form-filling
N44: 🚦 From the Traffic Source Breakdown
N46: Source | O46: Home → Confirmation Conv.
N47: Organic | O47: 43/303 = 14.2% ⭐
N48: Social | O48: 32/218 = 14.7% ⭐
N49: Paid | O49: 22/244 = 9.0% ⚠️
N50: Email | O50: 16/144 = 11.1%
N51: Direct | O51: 8/91 = 8.8% ⚠️
N53: This is your most valuable insight:
N55: Social and Organic traffic convert the best — these users have higher intent and trust
N56: Paid traffic converts the worst at 9% — you're spending money on ads but getting lower quality visitors. Either the ad targeting is off, or the landing page doesn't match the ad promise
N57: Email is mid-range — room to improve with better email segmentation
...
